Workbook

Sheet Summary
A1: EREQ-2147 UAT workbook: Expedited request option
A2: Prepared 2026-09-28 from the EREQ-2147 ticket, Harborline MSA (2023) + Amendment 2 (2026), Tri-County Services Agreement (2024). Due dates from business_days.py.
A3: PROVISIONAL: modules, severity rubric and holiday calendar are the SAMPLE reference files. Confirm with Heidy before sign-off (OQ-12).
A5: Module | B5: Cases | C5: S1 | D5: S2 | E5: S3 | F5: S4 | G5: Pass | H5: Fail | I5: Blocked | J5: Not run | K5: Blocked by OQ
A6: Requestor Portal - Intake | B6: =COUNTIF('Test cases'!$B$6:$B$205,"Requestor Portal - Intake") | C6: =COUNTIFS('Test cases'!$B$6:$B$205,"Requestor Portal - Intake",'Test cases'!$I$6:$I$205,"S1") | D6: =COUNTIFS('Test cases'!$B$6:$B$205,"Requestor Portal - Intake",'Test cases'!$I$6:$I$205,"S2") | E6: =COUNTIFS('Test cases'!$B$6:$B$205,"Requestor Portal - Intake",'Test cases'!$I$6:$I$205,"S3") | F6: =COUNTIFS('Test cases'!$B$6:$B$205,"Requestor Portal - Intake",'Test cases'!$I$6:$I$205,"S4") | G6: =COUNTIFS('Test cases'!$B$6:$B$205,"Requestor Portal - Intake",'Test cases'!$K$6:$K$205,"Pass") | H6: =COUNTIFS('Test cases'!$B$6:$B$205,"Requestor Portal - Intake",'Test cases'!$K$6:$K$205,"Fail") | I6: =COUNTIFS('Test cases'!$B$6:$B$205,"Requestor Portal - Intake",'Test cases'!$K$6:$K$205,"Blocked") | J6: =COUNTIFS('Test cases'!$B$6:$B$205,"Requestor Portal - Intake",'Test cases'!$K$6:$K$205,"Not run") | K6: =COUNTIFS('Test cases'!$B$6:$B$205,"Requestor Portal - Intake",'Test cases'!$J$6:$J$205,"OQ-*")
A7: Intake Processing | B7: =COUNTIF('Test cases'!$B$6:$B$205,"Intake Processing") | C7: =COUNTIFS('Test cases'!$B$6:$B$205,"Intake Processing",'Test cases'!$I$6:$I$205,"S1") | D7: =COUNTIFS('Test cases'!$B$6:$B$205,"Intake Processing",'Test cases'!$I$6:$I$205,"S2") | E7: =COUNTIFS('Test cases'!$B$6:$B$205,"Intake Processing",'Test cases'!$I$6:$I$205,"S3") | F7: =COUNTIFS('Test cases'!$B$6:$B$205,"Intake Processing",'Test cases'!$I$6:$I$205,"S4") | G7: =COUNTIFS('Test cases'!$B$6:$B$205,"Intake Processing",'Test cases'!$K$6:$K$205,"Pass") | H7: =COUNTIFS('Test cases'!$B$6:$B$205,"Intake Processing",'Test cases'!$K$6:$K$205,"Fail") | I7: =COUNTIFS('Test cases'!$B$6:$B$205,"Intake Processing",'Test cases'!$K$6:$K$205,"Blocked") | J7: =COUNTIFS('Test cases'!$B$6:$B$205,"Intake Processing",'Test cases'!$K$6:$K$205,"Not run") | K7: =COUNTIFS('Test cases'!$B$6:$B$205,"Intake Processing",'Test cases'!$J$6:$J$205,"OQ-*")
A8: Queue & Assignment | B8: =COUNTIF('Test cases'!$B$6:$B$205,"Queue & Assignment") | C8: =COUNTIFS('Test cases'!$B$6:$B$205,"Queue & Assignment",'Test cases'!$I$6:$I$205,"S1") | D8: =COUNTIFS('Test cases'!$B$6:$B$205,"Queue & Assignment",'Test cases'!$I$6:$I$205,"S2") | E8: =COUNTIFS('Test cases'!$B$6:$B$205,"Queue & Assignment",'Test cases'!$I$6:$I$205,"S3") | F8: =COUNTIFS('Test cases'!$B$6:$B$205,"Queue & Assignment",'Test cases'!$I$6:$I$205,"S4") | G8: =COUNTIFS('Test cases'!$B$6:$B$205,"Queue & Assignment",'Test cases'!$K$6:$K$205,"Pass") | H8: =COUNTIFS('Test cases'!$B$6:$B$205,"Queue & Assignment",'Test cases'!$K$6:$K$205,"Fail") | I8: =COUNTIFS('Test cases'!$B$6:$B$205,"Queue & Assignment",'Test cases'!$K$6:$K$205,"Blocked") | J8: =COUNTIFS('Test cases'!$B$6:$B$205,"Queue & Assignment",'Test cases'!$K$6:$K$205,"Not run") | K8: =COUNTIFS('Test cases'!$B$6:$B$205,"Queue & Assignment",'Test cases'!$J$6:$J$205,"OQ-*")
A9: Page Selection | B9: =COUNTIF('Test cases'!$B$6:$B$205,"Page Selection") | C9: =COUNTIFS('Test cases'!$B$6:$B$205,"Page Selection",'Test cases'!$I$6:$I$205,"S1") | D9: =COUNTIFS('Test cases'!$B$6:$B$205,"Page Selection",'Test cases'!$I$6:$I$205,"S2") | E9: =COUNTIFS('Test cases'!$B$6:$B$205,"Page Selection",'Test cases'!$I$6:$I$205,"S3") | F9: =COUNTIFS('Test cases'!$B$6:$B$205,"Page Selection",'Test cases'!$I$6:$I$205,"S4") | G9: =COUNTIFS('Test cases'!$B$6:$B$205,"Page Selection",'Test cases'!$K$6:$K$205,"Pass") | H9: =COUNTIFS('Test cases'!$B$6:$B$205,"Page Selection",'Test cases'!$K$6:$K$205,"Fail") | I9: =COUNTIFS('Test cases'!$B$6:$B$205,"Page Selection",'Test cases'!$K$6:$K$205,"Blocked") | J9: =COUNTIFS('Test cases'!$B$6:$B$205,"Page Selection",'Test cases'!$K$6:$K$205,"Not run") | K9: =COUNTIFS('Test cases'!$B$6:$B$205,"Page Selection",'Test cases'!$J$6:$J$205,"OQ-*")
A10: Redaction | B10: =COUNTIF('Test cases'!$B$6:$B$205,"Redaction") | C10: =COUNTIFS('Test cases'!$B$6:$B$205,"Redaction",'Test cases'!$I$6:$I$205,"S1") | D10: =COUNTIFS('Test cases'!$B$6:$B$205,"Redaction",'Test cases'!$I$6:$I$205,"S2") | E10: =COUNTIFS('Test cases'!$B$6:$B$205,"Redaction",'Test cases'!$I$6:$I$205,"S3") | F10: =COUNTIFS('Test cases'!$B$6:$B$205,"Redaction",'Test cases'!$I$6:$I$205,"S4") | G10: =COUNTIFS('Test cases'!$B$6:$B$205,"Redaction",'Test cases'!$K$6:$K$205,"Pass") | H10: =COUNTIFS('Test cases'!$B$6:$B$205,"Redaction",'Test cases'!$K$6:$K$205,"Fail") | I10: =COUNTIFS('Test cases'!$B$6:$B$205,"Redaction",'Test cases'!$K$6:$K$205,"Blocked") | J10: =COUNTIFS('Test cases'!$B$6:$B$205,"Redaction",'Test cases'!$K$6:$K$205,"Not run") | K10: =COUNTIFS('Test cases'!$B$6:$B$205,"Redaction",'Test cases'!$J$6:$J$205,"OQ-*")
A11: Billing | B11: =COUNTIF('Test cases'!$B$6:$B$205,"Billing") | C11: =COUNTIFS('Test cases'!$B$6:$B$205,"Billing",'Test cases'!$I$6:$I$205,"S1") | D11: =COUNTIFS('Test cases'!$B$6:$B$205,"Billing",'Test cases'!$I$6:$I$205,"S2") | E11: =COUNTIFS('Test cases'!$B$6:$B$205,"Billing",'Test cases'!$I$6:$I$205,"S3") | F11: =COUNTIFS('Test cases'!$B$6:$B$205,"Billing",'Test cases'!$I$6:$I$205,"S4") | G11: =COUNTIFS('Test cases'!$B$6:$B$205,"Billing",'Test cases'!$K$6:$K$205,"Pass") | H11: =COUNTIFS('Test cases'!$B$6:$B$205,"Billing",'Test cases'!$K$6:$K$205,"Fail") | I11: =COUNTIFS('Test cases'!$B$6:$B$205,"Billing",'Test cases'!$K$6:$K$205,"Blocked") | J11: =COUNTIFS('Test cases'!$B$6:$B$205,"Billing",'Test cases'!$K$6:$K$205,"Not run") | K11: =COUNTIFS('Test cases'!$B$6:$B$205,"Billing",'Test cases'!$J$6:$J$205,"OQ-*")
A12: Notifications | B12: =COUNTIF('Test cases'!$B$6:$B$205,"Notifications") | C12: =COUNTIFS('Test cases'!$B$6:$B$205,"Notifications",'Test cases'!$I$6:$I$205,"S1") | D12: =COUNTIFS('Test cases'!$B$6:$B$205,"Notifications",'Test cases'!$I$6:$I$205,"S2") | E12: =COUNTIFS('Test cases'!$B$6:$B$205,"Notifications",'Test cases'!$I$6:$I$205,"S3") | F12: =COUNTIFS('Test cases'!$B$6:$B$205,"Notifications",'Test cases'!$I$6:$I$205,"S4") | G12: =COUNTIFS('Test cases'!$B$6:$B$205,"Notifications",'Test cases'!$K$6:$K$205,"Pass") | H12: =COUNTIFS('Test cases'!$B$6:$B$205,"Notifications",'Test cases'!$K$6:$K$205,"Fail") | I12: =COUNTIFS('Test cases'!$B$6:$B$205,"Notifications",'Test cases'!$K$6:$K$205,"Blocked") | J12: =COUNTIFS('Test cases'!$B$6:$B$205,"Notifications",'Test cases'!$K$6:$K$205,"Not run") | K12: =COUNTIFS('Test cases'!$B$6:$B$205,"Notifications",'Test cases'!$J$6:$J$205,"OQ-*")
A13: Portal Delivery | B13: =COUNTIF('Test cases'!$B$6:$B$205,"Portal Delivery") | C13: =COUNTIFS('Test cases'!$B$6:$B$205,"Portal Delivery",'Test cases'!$I$6:$I$205,"S1") | D13: =COUNTIFS('Test cases'!$B$6:$B$205,"Portal Delivery",'Test cases'!$I$6:$I$205,"S2") | E13: =COUNTIFS('Test cases'!$B$6:$B$205,"Portal Delivery",'Test cases'!$I$6:$I$205,"S3") | F13: =COUNTIFS('Test cases'!$B$6:$B$205,"Portal Delivery",'Test cases'!$I$6:$I$205,"S4") | G13: =COUNTIFS('Test cases'!$B$6:$B$205,"Portal Delivery",'Test cases'!$K$6:$K$205,"Pass") | H13: =COUNTIFS('Test cases'!$B$6:$B$205,"Portal Delivery",'Test cases'!$K$6:$K$205,"Fail") | I13: =COUNTIFS('Test cases'!$B$6:$B$205,"Portal Delivery",'Test cases'!$K$6:$K$205,"Blocked") | J13: =COUNTIFS('Test cases'!$B$6:$B$205,"Portal Delivery",'Test cases'!$K$6:$K$205,"Not run") | K13: =COUNTIFS('Test cases'!$B$6:$B$205,"Portal Delivery",'Test cases'!$J$6:$J$205,"OQ-*")
A14: Reporting | B14: =COUNTIF('Test cases'!$B$6:$B$205,"Reporting") | C14: =COUNTIFS('Test cases'!$B$6:$B$205,"Reporting",'Test cases'!$I$6:$I$205,"S1") | D14: =COUNTIFS('Test cases'!$B$6:$B$205,"Reporting",'Test cases'!$I$6:$I$205,"S2") | E14: =COUNTIFS('Test cases'!$B$6:$B$205,"Reporting",'Test cases'!$I$6:$I$205,"S3") | F14: =COUNTIFS('Test cases'!$B$6:$B$205,"Reporting",'Test cases'!$I$6:$I$205,"S4") | G14: =COUNTIFS('Test cases'!$B$6:$B$205,"Reporting",'Test cases'!$K$6:$K$205,"Pass") | H14: =COUNTIFS('Test cases'!$B$6:$B$205,"Reporting",'Test cases'!$K$6:$K$205,"Fail") | I14: =COUNTIFS('Test cases'!$B$6:$B$205,"Reporting",'Test cases'!$K$6:$K$205,"Blocked") | J14: =COUNTIFS('Test cases'!$B$6:$B$205,"Reporting",'Test cases'!$K$6:$K$205,"Not run") | K14: =COUNTIFS('Test cases'!$B$6:$B$205,"Reporting",'Test cases'!$J$6:$J$205,"OQ-*")
A15: Admin & Configuration | B15: =COUNTIF('Test cases'!$B$6:$B$205,"Admin & Configuration") | C15: =COUNTIFS('Test cases'!$B$6:$B$205,"Admin & Configuration",'Test cases'!$I$6:$I$205,"S1") | D15: =COUNTIFS('Test cases'!$B$6:$B$205,"Admin & Configuration",'Test cases'!$I$6:$I$205,"S2") | E15: =COUNTIFS('Test cases'!$B$6:$B$205,"Admin & Configuration",'Test cases'!$I$6:$I$205,"S3") | F15: =COUNTIFS('Test cases'!$B$6:$B$205,"Admin & Configuration",'Test cases'!$I$6:$I$205,"S4") | G15: =COUNTIFS('Test cases'!$B$6:$B$205,"Admin & Configuration",'Test cases'!$K$6:$K$205,"Pass") | H15: =COUNTIFS('Test cases'!$B$6:$B$205,"Admin & Configuration",'Test cases'!$K$6:$K$205,"Fail") | I15: =COUNTIFS('Test cases'!$B$6:$B$205,"Admin & Configuration",'Test cases'!$K$6:$K$205,"Blocked") | J15: =COUNTIFS('Test cases'!$B$6:$B$205,"Admin & Configuration",'Test cases'!$K$6:$K$205,"Not run") | K15: =COUNTIFS('Test cases'!$B$6:$B$205,"Admin & Configuration",'Test cases'!$J$6:$J$205,"OQ-*")
A16: TOTAL | B16: =COUNTIF('Test cases'!$A$6:$A$205,"EREQ-2147-*") | C16: =COUNTIF('Test cases'!$I$6:$I$205,"S1") | D16: =COUNTIF('Test cases'!$I$6:$I$205,"S2") | E16: =COUNTIF('Test cases'!$I$6:$I$205,"S3") | F16: =COUNTIF('Test cases'!$I$6:$I$205,"S4") | G16: =COUNTIF('Test cases'!$K$6:$K$205,"Pass") | H16: =COUNTIF('Test cases'!$K$6:$K$205,"Fail") | I16: =COUNTIF('Test cases'!$K$6:$K$205,"Blocked") | J16: =COUNTIF('Test cases'!$K$6:$K$205,"Not run") | K16: =COUNTIF('Test cases'!$J$6:$J$205,"OQ-*")
A18: Open questions still unanswered | B18: =COUNTIF('Open questions'!$F$6:$F$105,"Open")
A19: S1 and S2 cases not yet passed | B19: =COUNTIFS('Test cases'!$I$6:$I$205,"S1",'Test cases'!$K$6:$K$205,"<>Pass",'Test cases'!$A$6:$A$205,"EREQ-2147-*")+COUNTIFS('Test cases'!$I$6:$I$205,"S2",'Test cases'!$K$6:$K$205,"<>Pass",'Test cases'!$A$6:$A$205,"EREQ-2147-*")
A20: Open defects | B20: =COUNTIFS('Defect log'!$G$6:$G$205,"<>",'Defect log'!$H$6:$H$205,"<>Closed")
A21: Exit criteria met? | B21: =IF(AND(B18=0,B19=0,COUNTIFS('Defect log'!$G$6:$G$205,"S1",'Defect log'!$H$6:$H$205,"<>Closed")=0,COUNTIFS('Defect log'!$G$6:$G$205,"S2",'Defect log'!$H$6:$H$205,"<>Closed")=0),"YES","NO")
A22: Teams status line (copy this cell) | B22: ="EREQ-2147 UAT: "&COUNTIF('Test cases'!$K$6:$K$205,"Pass")&" pass, "&COUNTIF('Test cases'!$K$6:$K$205,"Fail")&" fail, "&COUNTIF('Test cases'!$K$6:$K$205,"Blocked")&" blocked, "&COUNTIF('Test cases'!$K$6:$K$205,"Not run")&" not run of "&COUNTIF('Test cases'!$A$6:$A$205,"EREQ-2147-*")&" cases. "&COUNTIF('Open questions'!$F$6:$F$105,"Open")&" open questions. Exit criteria met: "&B21&"."

Sheet Test cases
A1: EREQ-2147 UAT workbook: Expedited request option
A2: Prepared 2026-09-28 from the EREQ-2147 ticket, Harborline MSA (2023) + Amendment 2 (2026), Tri-County Services Agreement (2024). Due dates from business_days.py.
A3: PROVISIONAL: modules, severity rubric and holiday calendar are the SAMPLE reference files. Confirm with Heidy before sign-off (OQ-12).
A5: Case ID | B5: Module | C5: Scenario | D5: Covers | E5: Preconditions | F5: Test data | G5: Steps | H5: Expected result | I5: Risk if it fails | J5: Blocked by | K5: Result | L5: Tester | M5: Defect ID | N5: Notes
A6: EREQ-2147-01 | B6: Requestor Portal - Intake | C6: Expedite checkbox appears on the intake form, unchecked by default | D6: AC-1, C-1 | E6: Standard setup (Test plan, entry criteria EC-1 to EC-5). | F6: RQ-01 portal login; client Harborline (CL-01) | G6: 1. Log in to the requestor portal as RQ-01. 2. Start a new request for claim CL-01. 3. Look at the intake form before touching any field. | H6: A checkbox labeled exactly "Expedite this request (+$35)" is on the form. It is unchecked when the form first loads. | I6: S2 | K6: Not run
A7: EREQ-2147-02 | B7: Requestor Portal - Intake | C7: Expedite choice is saved with the request | D7: AC-1, C-1 | E7: Standard setup (Test plan, entry criteria EC-1 to EC-5). Received time set by submitting at that time or by the test-env clock override (EC-5). | F7: R-A: RQ-01, CL-01, F-01, Expedite=Yes, received Mon 2026-10-05 09:00 ET | G7: 1. Log in to the portal as RQ-01. 2. Create a request for CL-01, upload F-01, check "Expedite this request (+$35)". 3. Submit on Mon 2026-10-05 at 09:00 ET. 4. In the Ecosystem, log in as U-03 and open the request. 5. Record the request number in Notes. Later cases reuse R-A. | H7: The Ecosystem request record shows Expedited = Yes. The portal request detail for RQ-01 also shows the request as expedited. | I7: S1 | K7: Not run
A8: EREQ-2147-03 | B8: Requestor Portal - Intake | C8: Unchecked request is saved as not expedited (control) | D8: AC-1, C-1, Regression | E8: Standard setup (Test plan, entry criteria EC-1 to EC-5). Received time set by submitting at that time or by the test-env clock override (EC-5). | F8: R-B: RQ-01, CL-01, F-01, Expedite=No, received Mon 2026-10-05 09:00 ET | G8: 1. As RQ-01, create the same request as R-A but leave the expedite checkbox unchecked. 2. Submit on Mon 2026-10-05 at 09:00 ET. 3. Open the request in the Ecosystem as U-03. 4. Record the request number in Notes. | H8: Request record shows Expedited = No. Due date = 2026-10-12 (Mon) (Harborline 5 business days). No EXPEDITE badge. | I8: S1 | K8: Not run
A9: EREQ-2147-04 | B9: Requestor Portal - Intake | C9: Checkbox state survives a validation error | D9: C-1, Gap | E9: Standard setup (Test plan, entry criteria EC-1 to EC-5). | F9: RQ-01; CL-01; F-01 | G9: 1. As RQ-01 start a request for CL-01 and check the expedite box. 2. Leave one required field blank and click Submit. 3. When the error shows, look at the checkbox. 4. Fill in the missing field and submit. 5. Open the request in the Ecosystem. | H9: After the error the checkbox is still checked. The submitted request shows Expedited = Yes. Only one request is created. | I9: S2 | K9: Not run
A10: EREQ-2147-05 | B10: Requestor Portal - Intake | C10: Intake regression with expedite checked: required fields, file types and sizes, duplicate submit | D10: C-1, Regression | E10: Standard setup (Test plan, entry criteria EC-1 to EC-5). | F10: RQ-01; CL-01; F-01 and F-08 (disallowed file type), F-09 (larger than the portal limit) | G10: 1. As RQ-01 start a request for CL-01, check expedite. 2. Try to upload F-08, then F-09. 3. Upload F-01 instead. 4. Remove one required field; try to submit; restore it. 5. Click Submit twice quickly. | H10: F-08 and F-09 are rejected with the same error messages as on a non-expedited request. Required-field validation is unchanged. Exactly one request is created (check the Ecosystem request list for CL-01 by RQ-01 at that minute). | I10: S2 | K10: Not run
A11: EREQ-2147-06 | B11: Requestor Portal - Intake | C11: Duplicate of an open non-expedited request, submitted as expedited | D11: C-1, Gap, Regression | E11: Standard setup (Test plan, entry criteria EC-1 to EC-5). R-B exists and is open. | F11: RQ-01; CL-01; F-01 (same as R-B) | G11: 1. As RQ-01 submit a new request identical to R-B, with expedite checked. 2. Check the portal response and the Ecosystem request list. | H11: If OQ-13 = blocked as a duplicate: the portal shows the existing duplicate warning, no new request is created, no fee is added. If OQ-13 = upgrade: no new request; R-B now shows Expedited = Yes with the due date recalculated from the upgrade time (Notes: record the time and date shown). Either way there is no second invoice. | I11: S2 | J11: OQ-13 | K11: Not run
A12: EREQ-2147-07 | B12: Requestor Portal - Intake | C12: Requestor who is not charged (Workers' Compensation Board) and the expedite option | D12: C-1, C-4, Gap | E12: Standard setup (Test plan, entry criteria EC-1 to EC-5). | F12: R-R: RQ-04, CL-04, F-07, Expedite=Try Yes, received Mon 2026-10-05 09:00 ET | G12: 1. Log in as RQ-04. 2. Start a request for CL-04 (Tri-County) and look for the expedite checkbox. 3. If it is there, check it and submit on Mon 2026-10-05 09:00 ET. 4. Open the request and its invoice in the Ecosystem. | H12: If OQ-2 = hidden for non-charged requestors: no checkbox; request due 2026-10-12 (Mon) (Tri-County Board, 5 business days); no invoice line. If OQ-2 = offered free: checkbox shown without "+$35", due 2026-10-07 (Wed), invoice shows no $35 line. If OQ-2 = offered and charged: label shows +$35, due 2026-10-07 (Wed), invoice shows Expedite fee $35.00. | I12: S2 | J12: OQ-2 | K12: Not run
A13: EREQ-2147-08 | B13: Requestor Portal - Intake | C13: Client with expedite switched off | D13: C-1, Gap | E13: Standard setup (Test plan, entry criteria EC-1 to EC-5). Expedite switched off for the Tri-County test client by U-02 (if the setting exists). | F13: RQ-01; CL-04; F-06 | G13: 1. Log in as RQ-01. 2. Start a request for CL-04 (Tri-County). 3. Look for the expedite checkbox; submit the request on Mon 2026-10-05 09:00 ET. | H13: If OQ-2 = per-client setting exists: no expedite checkbox for Tri-County (or the unavailable message CX specifies; record the wording). Request due 2026-10-19 (Mon) (10 business days). If OQ-2 = no per-client setting: the checkbox shows for every client; log it as a finding against OQ-2, not a defect. | I13: S2 | J13: OQ-2 | K13: Not run
A14: EREQ-2147-09 | B14: Requestor Portal - Intake | C14: Requestor removes or adds expedite after submission | D14: C-1, Gap | E14: Standard setup (Test plan, entry criteria EC-1 to EC-5). R-A and R-B submitted. | F14: R-A, R-B | G14: 1. As RQ-01 open R-A in the portal and try to uncheck expedite. 2. Open R-B and try to add expedite at a known time (record it). | H14: If OQ-8 = not allowed: no edit control; R-A stays due 2026-10-07 (Wed), R-B stays due 2026-10-12 (Mon). If OQ-8 = allowed: R-A reverts to 2026-10-12 (Mon) and the $35 line is removed; R-B's due date = 2 business days from the time you added it (run business_days.py due with that time) and a $35 line is added. | I14: S2 | J14: OQ-8 | K14: Not run
A15: EREQ-2147-10 | B15: Intake Processing | C15: Expedited request matched to the right claim and carrier | D15: C-1, Regression | E15: Standard setup (Test plan, entry criteria EC-1 to EC-5). | F15: R-A | G15: 1. As U-03 open R-A in Intake Processing. 2. Check the matched carrier, claim number and request type. | H15: Carrier = Harborline Mutual (TEST), claim = HMT-900001, request type = Authorization. Same values as the control request R-B. | I15: S1 | K15: Not run
A16: EREQ-2147-11 | B16: Intake Processing | C16: Associate enters an expedited request received by phone, fax or mail | D16: C-1, Gap | E16: Standard setup (Test plan, entry criteria EC-1 to EC-5). | F16: U-03; RQ-02; CL-01; F-01 | G16: 1. As U-03 create a request manually in Intake Processing for RQ-02 on CL-01, received Mon 2026-10-05 09:00 ET. 2. Look for an expedite option. | H16: If OQ-8 = associates can set expedite: option present; saved request shows Expedited = Yes, due 2026-10-07 (Wed), invoice shows Expedite fee $35.00. If OQ-8 = portal only: no option; due 2026-10-12 (Mon). | I16: S2 | J16: OQ-8 | K16: Not run
A17: EREQ-2147-12 | B17: Intake Processing | C17: Expedited request with a deficiency | D17: C-2, Gap | E17: Standard setup (Test plan, entry criteria EC-1 to EC-5). | F17: RQ-01; CL-01; authorization missing (no F-01) | G17: 1. As RQ-01 submit an expedited request for CL-01 without an authorization on Mon 2026-10-05 09:00 ET. 2. As U-03 issue the deficiency notice. 3. As RQ-01 upload F-01 on Wed 2026-10-07 10:00 ET. 4. Check the due date after each step. | H17: Deficiency notice is sent as today (regression). If OQ-6 = clock starts when complete: due 2026-10-09 (Fri). If OQ-6 = clock keeps running: due 2026-10-07 (Wed). If OQ-6 = paused: due date shown as paused, then recalculated when F-01 arrives (record values). | I17: S2 | J17: OQ-6 | K17: Not run
A18: EREQ-2147-13 | B18: Intake Processing | C18: Subpoena return date still captured on an expedited subpoena | D18: C-2, Regression, Contract | E18: Standard setup (Test plan, entry criteria EC-1 to EC-5). Received time set by submitting at that time or by the test-env clock override (EC-5). | F18: R-N: RQ-01, CL-02, F-04, Expedite=Yes, received Mon 2026-10-05 09:00 ET | G18: 1. As RQ-01 submit R-N (Harborline subpoena F-04, expedite checked). 2. As U-03 open it in Intake Processing. | H18: Request type = Subpoena. Return date field = 2026-10-20. Due date = 2026-10-07 (Wed) (2-day expedite is earlier than both the 3-day subpoena clock 2026-10-08 (Thu) and the return date, so no open question applies). | I18: S1 | K18: Not run
A19: EREQ-2147-14 | B19: Queue & Assignment | C19: Expedited due date, weekday morning | D19: AC-4, C-2 | E19: Standard setup (Test plan, entry criteria EC-1 to EC-5). Received time set by submitting at that time or by the test-env clock override (EC-5). | F19: R-A: RQ-01, CL-01, F-01, Expedite=Yes, received Mon 2026-10-05 09:00 ET | G19: 1. Open R-A in the review queue as U-01. 2. Read the due date. | H19: Due date = 2026-10-07 (Wed). The control R-B shows 2026-10-12 (Mon). | I19: S1 | K19: Not run
A20: EREQ-2147-15 | B20: Queue & Assignment | C20: Received exactly at the 5:00 pm cutoff | D20: C-2, Gap | E20: Standard setup (Test plan, entry criteria EC-1 to EC-5). Received time set by submitting at that time or by the test-env clock override (EC-5). | F20: R-C: RQ-02, CL-01, F-01, Expedite=Yes, received Mon 2026-10-05 17:00 ET | G20: 1. Submit R-C at exactly 17:00:00 ET. 2. Open it in the queue and read the due date. | H20: Due date = 2026-10-07 (Wed) (17:00 counts as the same day; the rule says AFTER 5:00 pm rolls over). | I20: S1 | K20: Not run
A21: EREQ-2147-16 | B21: Queue & Assignment | C21: Received one minute after cutoff | D21: C-2, Gap | E21: Standard setup (Test plan, entry criteria EC-1 to EC-5). Received time set by submitting at that time or by the test-env clock override (EC-5). | F21: R-D: RQ-02, CL-01, F-01, Expedite=Yes, received Mon 2026-10-05 17:01 ET | G21: 1. Submit R-D at 17:01 ET. 2. Read the due date in the queue. | H21: Day 0 = 2026-10-06. Due date = 2026-10-08 (Thu). | I21: S1 | K21: Not run
A22: EREQ-2147-17 | B22: Queue & Assignment | C22: Requestor in Pacific time submits at 3:00 pm local | D22: C-2, Gap | E22: Standard setup (Test plan, entry criteria EC-1 to EC-5). RQ-05 portal profile time zone = Pacific. | F22: R-E: RQ-05, CL-01, F-01, Expedite=Yes, received Mon 2026-10-05 18:00 ET | G22: 1. As RQ-05 submit R-E at 15:00 Pacific (18:00 ET). 2. Read the due date in the queue and in the portal. | H22: Due date = 2026-10-08 (Thu) in both places (the cutoff is 5:00 pm Eastern, so this counts as received the next business day). | I22: S1 | K22: Not run
A23: EREQ-2147-18 | B23: Queue & Assignment | C23: Clock crosses a weekend and Columbus Day | D23: C-2, Gap | E23: Standard setup (Test plan, entry criteria EC-1 to EC-5). Received time set by submitting at that time or by the test-env clock override (EC-5). | F23: R-F: RQ-01, CL-01, F-01, Expedite=Yes, received Thu 2026-10-08 10:00 ET | G23: 1. Submit R-F Thu 2026-10-08 10:00 ET. 2. Read the due date. | H23: If OQ-12 = SAMPLE calendar (Columbus Day is a business day): 2026-10-12 (Mon). If OQ-12 = Columbus Day observed: 2026-10-13 (Tue). | I23: S1 | J23: OQ-12 | K23: Not run
A24: EREQ-2147-19 | B24: Queue & Assignment | C24: Friday before cutoff | D24: C-2, Gap | E24: Standard setup (Test plan, entry criteria EC-1 to EC-5). Received time set by submitting at that time or by the test-env clock override (EC-5). | F24: R-G: RQ-01, CL-01, F-01, Expedite=Yes, received Fri 2026-10-09 16:59 ET | G24: 1. Submit R-G Fri 2026-10-09 16:59 ET. 2. Read the due date. | H24: Due date = 2026-10-13 (Tue). | I24: S1 | K24: Not run
A25: EREQ-2147-20 | B25: Queue & Assignment | C25: Friday after cutoff | D25: C-2, Gap | E25: Standard setup (Test plan, entry criteria EC-1 to EC-5). Received time set by submitting at that time or by the test-env clock override (EC-5). | F25: R-H: RQ-01, CL-01, F-01, Expedite=Yes, received Fri 2026-10-09 17:30 ET | G25: 1. Submit R-H Fri 2026-10-09 17:30 ET. 2. Read the due date. | H25: Day 0 = Mon 2026-10-12. Due date = 2026-10-14 (Wed). | I25: S1 | K25: Not run
A26: EREQ-2147-21 | B26: Queue & Assignment | C26: Received on a Saturday | D26: C-2, Gap | E26: Standard setup (Test plan, entry criteria EC-1 to EC-5). Received time set by submitting at that time or by the test-env clock override (EC-5). | F26: R-I: RQ-01, CL-01, F-01, Expedite=Yes, received Sat 2026-10-10 11:00 ET | G26: 1. Submit R-I Sat 2026-10-10 11:00 ET. 2. Read the due date. | H26: Day 0 = Mon 2026-10-12. Due date = 2026-10-14 (Wed). | I26: S1 | K26: Not run
A27: EREQ-2147-22 | B27: Queue & Assignment | C27: Day before Thanksgiving, before cutoff | D27: C-2, Gap | E27: Standard setup (Test plan, entry criteria EC-1 to EC-5). Clock override required (EC-5). | F27: R-J: RQ-01, CL-01, F-01, Expedite=Yes, received Wed 2026-11-25 16:00 ET | G27: 1. Set the test-env clock to Wed 2026-11-25 16:00 ET. 2. Submit R-J. 3. Read the due date. | H27: Due date = 2026-12-01 (Tue) (skips 2026-11-26, 11-27 and the weekend). | I27: S1 | K27: Not run
A28: EREQ-2147-23 | B28: Queue & Assignment | C28: Day before Thanksgiving, after cutoff | D28: C-2, Gap | E28: Standard setup (Test plan, entry criteria EC-1 to EC-5). Clock override required (EC-5). | F28: R-K: RQ-01, CL-01, F-01, Expedite=Yes, received Wed 2026-11-25 17:30 ET | G28: 1. Set the test-env clock to Wed 2026-11-25 17:30 ET. 2. Submit R-K. 3. Read the due date. | H28: Day 0 = Mon 2026-11-30. Due date = 2026-12-02 (Wed). | I28: S1 | K28: Not run
A29: EREQ-2147-24 | B29: Queue & Assignment | C29: Christmas Eve | D29: C-2, Gap | E29: Standard setup (Test plan, entry criteria EC-1 to EC-5). Clock override required (EC-5). | F29: R-L: RQ-01, CL-01, F-01, Expedite=Yes, received Thu 2026-12-24 10:00 ET | G29: 1. Set the test-env clock to Thu 2026-12-24 10:00 ET. 2. Submit R-L. 3. Read the due date. | H29: If OQ-12 = SAMPLE calendar (Dec 24 is a business day): 2026-12-29 (Tue). If OQ-12 = Dec 24 observed: 2026-12-30 (Wed). | I29: S1 | J29: OQ-12 | K29: Not run
A30: EREQ-2147-25 | B30: Queue & Assignment | C30: Expedited Harborline subpoena with a return date earlier than 2 business days | D30: C-2, Gap, Contract | E30: Standard setup (Test plan, entry criteria EC-1 to EC-5). Received time set by submitting at that time or by the test-env clock override (EC-5). | F30: R-M: RQ-01, CL-02, F-03, Expedite=Yes, received Mon 2026-10-05 09:00 ET | G30: 1. Submit R-M (return date Tue 2026-10-06, expedite checked) Mon 2026-10-05 09:00 ET. 2. Read the due date in the queue. 3. Submit the same subpoena WITHOUT expedite and read its due date. | H30: Not expedited: due 2026-10-06 (return date is earlier than 3 business days, 2026-10-08 (Thu)). Expedited: if OQ-1 = earlier date wins: due 2026-10-06. If OQ-1 = expedite replaces the clock (ticket as written): due 2026-10-07 (Wed); log a contract conflict against Harborline Amendment 2 Sec. 2.2 for CX to decide. | I30: S1 | J30: OQ-1 | K30: Not run
A31: EREQ-2147-26 | B31: Queue & Assignment | C31: Tri-County court order, expedited | D31: C-2, Gap, Contract | E31: Standard setup (Test plan, entry criteria EC-1 to EC-5). Received time set by submitting at that time or by the test-env clock override (EC-5). Record the court-order clock currently configured for Tri-County (U-02, Admin). | F31: R-S: RQ-01, CL-03, F-05, Expedite=Yes, received Mon 2026-10-05 09:00 ET | G31: 1. Note the configured Tri-County court-order clock. 2. Submit R-S Mon 2026-10-05 09:00 ET. 3. Read the due date. | H31: If OQ-1 = earlier date wins: due = the earlier of 2026-10-07 (Wed) and the court-order due date (run business_days.py due with the configured clock). If OQ-1 = expedite replaces the clock: due 2026-10-07 (Wed). | I31: S1 | J31: OQ-1 | K31: Not run
A32: EREQ-2147-27 | B32: Queue & Assignment | C32: Non-expedited Harborline requests keep the amended contract clocks | D32: Regression, Contract | E32: Standard setup (Test plan, entry criteria EC-1 to EC-5). Received time set by submitting at that time or by the test-env clock override (EC-5). | F32: R-B: RQ-01, CL-01, F-01, Expedite=No, received Mon 2026-10-05 09:00 ET; R-O: RQ-01, CL-02, F-04, Expedite=No, received Mon 2026-10-05 09:00 ET | G32: 1. Open R-B and R-O in the queue. 2. Read both due dates. | H32: R-B due 2026-10-12 (Mon) (5 business days, Amendment 2 Sec. 2.1; NOT 2026-10-14 (Wed) from the superseded 2023 MSA). R-O due 2026-10-08 (Thu) (3 business days, Amendment 2 Sec. 2.2). | I32: S1 | K32: Not run
A33: EREQ-2147-28 | B33: Queue & Assignment | C33: Tri-County: expedited vs contracted clock | D33: C-2, Regression, Contract | E33: Standard setup (Test plan, entry criteria EC-1 to EC-5). Received time set by submitting at that time or by the test-env clock override (EC-5). | F33: R-P: RQ-01, CL-03, F-06, Expedite=Yes, received Mon 2026-10-05 09:00 ET; R-Q: RQ-01, CL-04, F-06, Expedite=No, received Mon 2026-10-05 09:00 ET | G33: 1. Open R-P and R-Q in the queue. 2. Read both due dates. | H33: R-P (expedited) due 2026-10-07 (Wed). R-Q (not expedited) due 2026-10-19 (Mon) (10 business days, Sec. 2.1). | I33: S1 | K33: Not run
A34: EREQ-2147-29 | B34: Queue & Assignment | C34: Expedited requests sort above non-expedited requests | D34: AC-2, C-3 | E34: Standard setup (Test plan, entry criteria EC-1 to EC-5). R-A, R-B, R-O, R-Q and at least 3 other non-expedited requests in the same reviewer queue. | F34: R-A, R-B, R-O, R-Q | G34: 1. Log in as U-01 and open the review queue with the default sort. 2. Note the position of each test request. | H34: Every expedited request (R-A) is listed above every non-expedited request (R-B, R-O, R-Q and the others). | I34: S2 | K34: Not run
A35: EREQ-2147-30 | B35: Queue & Assignment | C35: EXPEDITE badge shows on expedited requests only | D35: AC-2, C-3 | E35: Standard setup (Test plan, entry criteria EC-1 to EC-5). | F35: R-A, R-B | G35: 1. As U-01 view the queue. 2. Open R-A, then R-B. | H35: R-A shows a red badge reading "EXPEDITE" in the queue row and on the request detail. R-B shows no badge in either place. | I35: S2 | K35: Not run
A36: EREQ-2147-31 | B36: Queue & Assignment | C36: Order among expedited requests, including due-date ties | D36: C-3, Gap | E36: Standard setup (Test plan, entry criteria EC-1 to EC-5). R-A, R-C, R-D, R-H and R-I in one queue. | F36: R-A, R-C (both due 2026-10-07), R-D (due 2026-10-08), R-H, R-I (both due 2026-10-14) | G36: 1. As U-01 open the queue with default sort. 2. Note the order of the five requests. | H36: If OQ-9 = due date, ties broken by received time: R-A, R-C, R-D, R-H, R-I. If OQ-9 = another tiebreaker (e.g. request number or client): R-D is still third; record the order of each tied pair and the rule. | I36: S2 | J36: OQ-9 | K36: Not run | N36: With one 2-day clock, due-date order and received-time order agree; only the tiebreaker is open.
A37: EREQ-2147-32 | B37: Queue & Assignment | C37: Expedited request vs non-expedited subpoena due sooner | D37: C-3, Gap, Contract | E37: Standard setup (Test plan, entry criteria EC-1 to EC-5). Non-expedited R-M variant (return date 2026-10-06, due 2026-10-06) and R-A (expedited, due 2026-10-07) in one queue. | F37: R-M (not expedited), R-A | G37: 1. As U-01 open the queue. 2. Note which is higher. | H37: If OQ-9 = due date first: the subpoena due 2026-10-06 is above R-A. If OQ-9 = expedite always on top (ticket as written): R-A is above the subpoena; log a contract risk against Harborline Amendment 2 Sec. 2.2. | I37: S1 | J37: OQ-9 | K37: Not run
A38: EREQ-2147-33 | B38: Queue & Assignment | C38: Reassignment keeps badge, due date and position | D38: C-3, Regression | E38: Standard setup (Test plan, entry criteria EC-1 to EC-5). | F38: R-A; reviewers U-01 and U-04 | G38: 1. As a supervisor reassign R-A from U-01 to U-04. 2. Log in as U-04 and open the queue. | H38: R-A is in U-04's queue above non-expedited requests, shows the EXPEDITE badge, and the due date is still 2026-10-07 (Wed). | I38: S2 | K38: Not run
A39: EREQ-2147-34 | B39: Queue & Assignment | C39: Non-expedited requests keep their existing order | D39: C-3, Regression | E39: Standard setup (Test plan, entry criteria EC-1 to EC-5). Before any expedited request exists, screenshot U-01's queue with R-B, R-O, R-Q and 3 other non-expedited requests (baseline). | F39: R-B, R-O, R-Q; R-A added after the baseline | G39: 1. Take the baseline screenshot. 2. Submit R-A (expedited). 3. As U-01 reopen the queue with the default sort. | H39: R-A is on top. Below it, the non-expedited requests are in exactly the baseline order (compare row by row with the screenshot; attach both to Notes). | I39: S2 | K39: Not run
A40: EREQ-2147-35 | B40: Queue & Assignment | C40: Expedited adverse-carrier request waiting for claim rep approval | D40: C-2, Gap, Contract | E40: Standard setup (Test plan, entry criteria EC-1 to EC-5). Received time set by submitting at that time or by the test-env clock override (EC-5). | F40: R-T: RQ-03, CL-01, F-01, Expedite=Yes, received Mon 2026-10-05 09:00 ET | G40: 1. Submit R-T Mon 2026-10-05 09:00 ET. 2. As U-01 complete page selection but do not record the Harborline claim rep approval. 3. On 2026-10-07 check the due date and status. | H40: Release is blocked until approval is recorded (MSA Sec. 3.2, regression). If OQ-6 = clock paused while on hold: status shows on hold, due date not counted as missed. If OQ-6 = clock keeps running: due 2026-10-07 (Wed) shows as at risk on 2026-10-07. | I40: S1 | J40: OQ-6 | K40: Not run
A41: EREQ-2147-36 | B41: Page Selection | C41: Harborline withheld categories still applied on an expedited request | D41: Regression, Contract | E41: Standard setup (Test plan, entry criteria EC-1 to EC-5). | F41: R-A; CL-01 file contains SIU note (p.4), reserve worksheet (p.7), mental health treatment note (p.9) | G41: 1. As U-01 run page selection on R-A. 2. Check the pages marked withheld. | H41: Pages 4, 7 and 9 are withheld in full (MSA Sec. 3.1; Amendment 2 Sec. 3.4, authorization F-01 does not name mental health). Same page count released as on control R-B. | I41: S1 | K41: Not run
...

Sheet Traceability
A1: EREQ-2147 UAT workbook: Expedited request option
A2: Prepared 2026-09-28 from the EREQ-2147 ticket, Harborline MSA (2023) + Amendment 2 (2026), Tri-County Services Agreement (2024). Due dates from business_days.py.
A3: PROVISIONAL: modules, severity rubric and holiday calendar are the SAMPLE reference files. Confirm with Heidy before sign-off (OQ-12).
A5: ID | B5: Type | C5: Text | D5: Covered by | E5: Case count (live)
A6: AC-1 | B6: Acceptance criterion | C6: Checkbox appears on the intake form and is saved with the request. | D6: EREQ-2147-01, EREQ-2147-02, EREQ-2147-03 | E6: =SUMPRODUCT(--ISNUMBER(FIND(", AC-1,",", "&'Test cases'!$D$6:$D$205&",")))
A7: AC-2 | B7: Acceptance criterion | C7: Expedited requests show the badge and sort first in the queue. | D7: EREQ-2147-29, EREQ-2147-30 | E7: =SUMPRODUCT(--ISNUMBER(FIND(", AC-2,",", "&'Test cases'!$D$6:$D$205&",")))
A8: AC-3 | B8: Acceptance criterion | C8: Invoice shows the $35 line. | D8: EREQ-2147-41 | E8: =SUMPRODUCT(--ISNUMBER(FIND(", AC-3,",", "&'Test cases'!$D$6:$D$205&",")))
A9: AC-4 | B9: Acceptance criterion | C9: Confirmation email shows the correct due date. | D9: EREQ-2147-14, EREQ-2147-47, EREQ-2147-48, EREQ-2147-49, EREQ-2147-50 | E9: =SUMPRODUCT(--ISNUMBER(FIND(", AC-4,",", "&'Test cases'!$D$6:$D$205&",")))
A10: C-1 | B10: Change | C10: Add an "Expedite this request (+$35)" checkbox to the requestor portal intake form. | D10: EREQ-2147-01, EREQ-2147-02, EREQ-2147-03, EREQ-2147-04, EREQ-2147-05, EREQ-2147-06, EREQ-2147-07, EREQ-2147-08, EREQ-2147-09, EREQ-2147-10, EREQ-2147-11, EREQ-2147-59, EREQ-2147-60 | E10: =SUMPRODUCT(--ISNUMBER(FIND(", C-1,",", "&'Test cases'!$D$6:$D$205&",")))
A11: C-2 | B11: Change | C11: Expedited requests get a 2-business-day turnaround clock instead of the client's contracted clock. | D11: EREQ-2147-12, EREQ-2147-13, EREQ-2147-14, EREQ-2147-15, EREQ-2147-16, EREQ-2147-17, EREQ-2147-18, EREQ-2147-19, EREQ-2147-20, EREQ-2147-21, EREQ-2147-22, EREQ-2147-23, EREQ-2147-24, EREQ-2147-25, EREQ-2147-26, EREQ-2147-28, EREQ-2147-35, EREQ-2147-46, EREQ-2147-53, EREQ-2147-56 | E11: =SUMPRODUCT(--ISNUMBER(FIND(", C-2,",", "&'Test cases'!$D$6:$D$205&",")))
A12: C-3 | B12: Change | C12: Expedited requests go to the top of the review queue and show a red EXPEDITE badge. | D12: EREQ-2147-29, EREQ-2147-30, EREQ-2147-31, EREQ-2147-32, EREQ-2147-33, EREQ-2147-34 | E12: =SUMPRODUCT(--ISNUMBER(FIND(", C-3,",", "&'Test cases'!$D$6:$D$205&",")))
A13: C-4 | B13: Change | C13: Billing adds a $35 "Expedite fee" line to the requestor invoice. | D13: EREQ-2147-07, EREQ-2147-41, EREQ-2147-42, EREQ-2147-43, EREQ-2147-44, EREQ-2147-45, EREQ-2147-46, EREQ-2147-52 | E13: =SUMPRODUCT(--ISNUMBER(FIND(", C-4,",", "&'Test cases'!$D$6:$D$205&",")))
A14: C-5 | B14: Change | C14: The requestor gets a confirmation email stating the expedited due date. | D14: EREQ-2147-47, EREQ-2147-48, EREQ-2147-49, EREQ-2147-50, EREQ-2147-51 | E14: =SUMPRODUCT(--ISNUMBER(FIND(", C-5,",", "&'Test cases'!$D$6:$D$205&",")))
A15: C-6 | B15: Change | C15: Add an "Expedited" filter and column to the daily SLA report. | D15: EREQ-2147-54, EREQ-2147-55, EREQ-2147-56, EREQ-2147-58 | E15: =SUMPRODUCT(--ISNUMBER(FIND(", C-6,",", "&'Test cases'!$D$6:$D$205&",")))
A16: (none) | B16: Note | C16: No acceptance criterion covers C-2 (the due date on the request itself) or C-6 (SLA report). Cases were written for both anyway; CX should add ACs.

Sheet Contract conflicts
A1: EREQ-2147 UAT workbook: Expedited request option
A2: Prepared 2026-09-28 from the EREQ-2147 ticket, Harborline MSA (2023) + Amendment 2 (2026), Tri-County Services Agreement (2024). Due dates from business_days.py.
A3: PROVISIONAL: modules, severity rubric and holiday calendar are the SAMPLE reference files. Confirm with Heidy before sign-off (OQ-12).
A5: Client | B5: Clause | C5: What it says | D5: How EREQ-2147 interacts | E5: Finding | F5: Covering case(s) | G5: Open question
A6: Harborline Mutual | B6: Amendment 2, Sec. 2.2 (replaces MSA 2.2) | C6: Subpoenas within 3 business days of receipt or by the return date, whichever is earlier. | D6: Ticket says the 2-day clock applies "instead of" the contracted clock. A subpoena with a return date 1 day out would get a LATER due date by being expedited. | E6: Conflict | F6: EREQ-2147-25, EREQ-2147-32 | G6: OQ-1, OQ-9
A7: Harborline Mutual | B7: Amendment 2, Sec. 2.1 (replaces MSA 2.1) | C7: Complete requests within 5 business days (was 7 in the 2023 MSA). | D7: Expedite (2 days) is shorter, so no conflict. Confirms the non-expedited clock is 5, not 7. | E7: Regression | F7: EREQ-2147-27
A8: Harborline Mutual | B8: Amendment 2, Sec. 2.4 | C8: 2% monthly service credit if more than 5% of requests miss the Sec. 2.1 turnaround. | D8: Expedited requests jump the queue, which pushes standard requests later. The report must also pick one clock for 'missed'. | E8: Risk | F8: EREQ-2147-56, EREQ-2147-34 | G8: OQ-4
A9: Harborline Mutual | B9: MSA Sec. 2.3 | C9: Weekly service level report to the carrier: volume, turnaround, missed service levels. | D9: New Expedited data and a second clock; not stated whether carriers see it. | E9: Risk | F9: EREQ-2147-58 | G9: OQ-11
A10: Harborline Mutual | B10: MSA Sec. 3.2 | C10: Written claim rep approval before releasing to an adverse carrier. | D10: A paid 2-day promise ClaimFox can't control while waiting for approval. | E10: Conflict | F10: EREQ-2147-35, EREQ-2147-39 | G10: OQ-6
A11: Harborline Mutual | B11: MSA Sec. 3.1, 3.3; Amendment 2 Sec. 3.4 | C11: Withhold SIU, reserve and valuation pages; extra redactions (DL, plates, VINs); withhold mental health unless authorization names it. | D11: No rule change, but a compressed clock raises the risk of a rushed review. Must regression-test on expedited requests. | E11: Regression | F11: EREQ-2147-36, EREQ-2147-37, EREQ-2147-40
A12: Harborline Mutual | B12: MSA Sec. 4.4 | C12: No automated decision-making on what is released without carrier approval. | D12: Only relevant if expedite is met by routing to any automated page selection. Confirm with Heidy (entry criterion EC-6). | E12: Regression | F12: (entry criterion EC-6)
A13: Harborline Mutual | B13: (silent) | C13: No clause on fees charged to requestors. | D13: Ticket charges Harborline's requestors $35. Not prohibited, not authorized. | E13: Not specified | F13: EREQ-2147-41, EREQ-2147-58 | G13: OQ-11
A14: Tri-County WC Fund | B14: Sec. 2.1 | C14: Complete requests within 10 business days. | D14: Expedite is shorter; no conflict. | E14: Regression | F14: EREQ-2147-28
A15: Tri-County WC Fund | B15: Sec. 2.2 | C15: Workers' Compensation Board requests within 5 business days. | D15: The Board is a state agency and likely not charged. Ticket doesn't say whether it can expedite or pays $35. | E15: Not specified | F15: EREQ-2147-07 | G15: OQ-2
A16: Tri-County WC Fund | B16: Sec. 2.3 | C16: Requests with a court order "handled promptly". | D16: "Promptly" is undefined, so it's unclear whether 2 days is faster or slower than what is owed. | E16: Unclear | F16: EREQ-2147-26 | G16: OQ-1
A17: Tri-County WC Fund | B17: Sec. 3.1, 3.2 | C17: Withhold psychiatric records, 42 CFR Part 2 records and HIV information without specific authorization. | D17: No rule change; regression on expedited requests. | E17: Regression | F17: EREQ-2147-38
A18: Tri-County WC Fund | B18: Sec. 6.1 | C18: Monthly activity report by the 10th business day. | D18: Report must still total correctly with expedited requests. | E18: Regression | F18: EREQ-2147-58, EREQ-2147-57 | G18: OQ-11

Sheet Due-date matrix
A1: EREQ-2147 UAT workbook: Expedited request option
A2: Prepared 2026-09-28 from the EREQ-2147 ticket, Harborline MSA (2023) + Amendment 2 (2026), Tri-County Services Agreement (2024). Due dates from business_days.py.
A3: PROVISIONAL: modules, severity rubric and holiday calendar are the SAMPLE reference files. Confirm with Heidy before sign-off (OQ-12).
A5: Received | B5: Day 0 | C5: Expedite (2 bd) | D5: Harborline standard (5 bd) | E5: Harborline subpoena (3 bd) | F5: Tri-County standard (10 bd) | G5: Tri-County WCB (5 bd) | H5: Harborline 2023 MSA (superseded) (7 bd) | I5: Used by test requests
A6: Mon 2026-10-05 09:00 ET | B6: 46300 | C6: 46302 | D6: 46307 | E6: 46303 | F6: 46314 | G6: 46307 | H6: 46309 | I6: R-A, R-B, R-M, R-N, R-O, R-P, R-Q, R-R, R-S, R-T, R-U
A7: Mon 2026-10-05 17:00 ET | B7: 46300 | C7: 46302 | D7: 46307 | E7: 46303 | F7: 46314 | G7: 46307 | H7: 46309 | I7: R-C
A8: Mon 2026-10-05 17:01 ET | B8: 46301 | C8: 46303 | D8: 46308 | E8: 46304 | F8: 46315 | G8: 46308 | H8: 46310 | I8: R-D
A9: Mon 2026-10-05 18:00 ET | B9: 46301 | C9: 46303 | D9: 46308 | E9: 46304 | F9: 46315 | G9: 46308 | H9: 46310 | I9: R-E
A10: Thu 2026-10-08 10:00 ET | B10: 46303 | C10: 46307 | D10: 46310 | E10: 46308 | F10: 46317 | G10: 46310 | H10: 46314 | I10: R-F
A11: Fri 2026-10-09 16:59 ET | B11: 46304 | C11: 46308 | D11: 46311 | E11: 46309 | F11: 46318 | G11: 46311 | H11: 46315 | I11: R-G
A12: Fri 2026-10-09 17:30 ET | B12: 46307 | C12: 46309 | D12: 46314 | E12: 46310 | F12: 46321 | G12: 46314 | H12: 46316 | I12: R-H
A13: Sat 2026-10-10 11:00 ET | B13: 46307 | C13: 46309 | D13: 46314 | E13: 46310 | F13: 46321 | G13: 46314 | H13: 46316 | I13: R-I
A14: Wed 2026-11-25 16:00 ET | B14: 46351 | C14: 46357 | D14: 46360 | E14: 46358 | F14: 46367 | G14: 46360 | H14: 46364 | I14: R-J
A15: Wed 2026-11-25 17:30 ET | B15: 46356 | C15: 46358 | D15: 46363 | E15: 46359 | F15: 46370 | G15: 46363 | H15: 46365 | I15: R-K
A16: Thu 2026-12-24 10:00 ET | B16: 46380 | C16: 46385 | D16: 46391 | E16: 46386 | F16: 46398 | G16: 46391 | H16: 46393 | I16: R-L
A17: Alt: Thu 2026-10-08 10:00 ET, Columbus Day observed | B17: 46303 | C17: 46308 | I17: R-F if OQ-12
A18: Alt: Thu 2026-12-24 10:00 ET, Christmas Eve observed | B18: 46384 | C18: 46386 | I18: R-L if OQ-12

Sheet Open questions
A1: EREQ-2147 UAT workbook: Expedited request option
A2: Prepared 2026-09-28 from the EREQ-2147 ticket, Harborline MSA (2023) + Amendment 2 (2026), Tri-County Services Agreement (2024). Due dates from business_days.py.
A3: PROVISIONAL: modules, severity rubric and holiday calendar are the SAMPLE reference files. Confirm with Heidy before sign-off (OQ-12).
A5: ID | B5: Question | C5: Why it matters | D5: Who should answer | E5: Blocks cases | F5: Status | G5: Answer
A6: OQ-1 | B6: When the client's contracted deadline is EARLIER than 2 business days, which due date wins? The ticket says the 2-day clock applies "instead of the client's contracted clock". | C6: Harborline Amendment 2, Sec. 2.2 requires subpoenas by the return date if earlier. A subpoena with a return date tomorrow would get a LATER due date by being expedited: a contract breach the requestor paid $35 for. Tri-County Sec. 2.3 (court orders "promptly") has the same problem. | D6: CX (ticket owner) with Client Services | E6: EREQ-2147-25, EREQ-2147-26 | F6: Open
A7: OQ-2 | B7: Who is eligible? (a) Can expedite be switched on or off per client, and who can change it? (b) Is it offered to requestors who aren't charged (e.g. the Workers' Compensation Board, state agencies), and if so do they pay $35? (c) What does a requestor see when it is unavailable? | C7: The ticket has no per-client control, no admin setting and no rule for non-charged requestors. Tri-County Sec. 2.2 gives the Board a 5-day clock and the Board is not a paying requestor. | D7: CX with Heidy (dev) | E7: EREQ-2147-07, EREQ-2147-08, EREQ-2147-59, EREQ-2147-60 | F7: Open
A8: OQ-3 | B8: If ClaimFox misses the 2-day expedited due date, is the $35 refunded, credited, or kept? Automatically or on request? | C8: The ticket sells a paid promise with no remedy. Customer service will get this question on the first late request. | D8: CX with Finance | E8: EREQ-2147-46 | F8: Open
A9: OQ-4 | B9: Which clock defines a MISSED SLA for an expedited request in the SLA report and client reports: the 2-day expedite clock or the client's contracted clock? | C9: Harborline Amendment 2, Sec. 2.4: a 2% service credit if more than 5% of requests miss the 5-day turnaround in a month. Counting expedite misses against 2 days could overstate misses in the carrier report (MSA Sec. 2.3); ignoring them hides broken promises to requestors. | D9: Client Services (account owners) with the reporting owner | E9: EREQ-2147-56 | F9: Open
A10: OQ-5 | B10: If an expedited request is cancelled, is the $35 refunded or removed from the invoice? Does it depend on whether work has started? | C10: Billing regression always tests cancellations; the ticket gives no rule. | D10: Finance with CX | E10: EREQ-2147-45 | F10: Open
A11: OQ-6 | B11: Does the 2-day clock pause, restart or keep running while a request is deficient (deficiency notice) or on hold, e.g. a Harborline adverse-carrier request waiting for the claim rep's written approval (MSA Sec. 3.2)? | C11: ClaimFox doesn't control how long the requestor or the carrier takes. A running clock means guaranteed misses (and refund questions, OQ-3). | D11: CX with Operations | E11: EREQ-2147-12, EREQ-2147-35 | F11: Open
A12: OQ-7 | B12: What event meets the expedited due date: records ready for release, invoice issued, or files released? Portal Delivery only releases after payment, and payment timing is up to the requestor. | C12: Decides whether a request is on time in reports and whether a refund (OQ-3) is owed. | D12: CX with Operations | E12: EREQ-2147-53 | F12: Open
A13: OQ-8 | B13: Can expedite be added or removed after submission, by the requestor in the portal or by a ClaimFox associate (e.g. a request that came in by phone, fax or mail)? If added later, when does the 2-day clock start? | C13: The ticket only covers the portal intake form. Associates will be asked to upgrade requests on day one. | D13: CX with Heidy (dev) | E13: EREQ-2147-09, EREQ-2147-11 | F13: Open
A14: OQ-9 | B14: How does the queue order (a) expedited requests among themselves and (b) an expedited request against a non-expedited one with an EARLIER due date (e.g. a subpoena due tomorrow)? | C14: "Top of the queue" taken literally can push a request due tomorrow below one due in two days, which can cause a contract miss. | D14: Operations lead | E14: EREQ-2147-31, EREQ-2147-32 | F14: Open
A15: OQ-10 | B15: Is the $35 fee allowed and taxable in every state on the fee schedule? Do any state record-fee caps limit it? | C15: Billing applies fee schedules by state. A fee the state doesn't allow is a refund and compliance problem across many invoices. | D15: Finance with Legal | E15: EREQ-2147-44 | F15: Open
A16: OQ-11 | B16: Do Harborline and Tri-County need to agree to ClaimFox charging their requestors an expedite fee and running a different clock on their files? Should the Expedited column appear in carrier-facing reports (Harborline weekly SLA report, Tri-County monthly activity report)? | C16: Neither contract mentions requestor fees or expedite. Both require service-level reporting to the client. | D16: Client Services (account owners) | E16: EREQ-2147-58 | F16: Open
A17: OQ-12 | B17: Which holidays does ClaimFox observe, and is 5:00 pm Eastern the cutoff for expedited requests too? The SAMPLE calendar treats Columbus Day (2026-10-12), Veterans Day (2026-11-11) and Christmas Eve (2026-12-24) as business days. | C17: Changes the expected due date in the weekend and holiday cases. On a 2-day clock one holiday is a 50% error. | D17: Heidy (dev) with Operations | E17: EREQ-2147-18, EREQ-2147-24 | F17: Open
A18: OQ-13 | B18: If an expedited request duplicates an open non-expedited request on the same claim from the same requestor, what happens: blocked as a duplicate, or the open request is upgraded? | C18: Duplicate detection is a standard intake regression check. Without a rule the requestor could pay for a request that never runs. | D18: CX with Heidy (dev) | E18: EREQ-2147-06 | F18: Open

Sheet Test data
A1: EREQ-2147 UAT workbook: Expedited request option
A2: Prepared 2026-09-28 from the EREQ-2147 ticket, Harborline MSA (2023) + Amendment 2 (2026), Tri-County Services Agreement (2024). Due dates from business_days.py.
A3: PROVISIONAL: modules, severity rubric and holiday calendar are the SAMPLE reference files. Confirm with Heidy before sign-off (OQ-12).
A5: Type | B5: ID | C5: Name / value | D5: Details | E5: Time zone
A6: Requestor | B6: RQ-01 | C6: Marlow & Pike LLP (TEST) | D6: Plaintiff firm, charged. Portal login rq01.test@example.com | E6: Eastern
A7: Requestor | B7: RQ-02 | C7: Brightline Record Retrieval (TEST) | D7: Record retrieval company, charged. rq02.test@example.com | E7: Eastern
A8: Requestor | B8: RQ-03 | C8: Coastal Ridge Insurance (TEST) | D8: Adverse carrier (Harborline MSA 3.2 applies). rq03.test@example.com | E8: Eastern
A9: Requestor | B9: RQ-04 | C9: State Workers' Compensation Board (TEST) | D9: State agency, not charged (Tri-County 2.2). rq04.test@example.com | E9: Eastern
A10: Requestor | B10: RQ-05 | C10: Ferris Legal Group (TEST) | D10: Plaintiff firm, charged, profile time zone Pacific. rq06.test@example.com | E10: Pacific
A11: Claim | B11: CL-01 | C11: Harborline HMT-900001, claimant "Test Claimant Alpha", auto liability | D11: File (40 pp): SIU note p.4, reserve worksheet p.7, mental health note p.9; SSN, DOB, bank account; other driver's DL, plate, VIN
A12: Claim | B12: CL-02 | C12: Harborline HMT-900002, claimant "Test Claimant Bravo" | D12: Standard file, used for subpoenas
A13: Claim | B13: CL-03 | C13: Tri-County TCT-800001, claimant "Test Claimant Charlie", workers' comp | D13: File: psychiatric note p.3, 42 CFR Part 2 record p.5, HIV lab p.8
A14: Claim | B14: CL-04 | C14: Tri-County TCT-800002, claimant "Test Claimant Delta" | D14: Standard file
A15: File | B15: F-01 | C15: authorization_general_TEST.pdf | D15: General authorization, does not name mental health
A16: File | B16: F-02 | C16: authorization_mental_health_TEST.pdf | D16: Names mental health records
A17: File | B17: F-03 | C17: subpoena_return_2026-10-06_TEST.pdf | D17: Subpoena, return date Tue 2026-10-06
A18: File | B18: F-04 | C18: subpoena_return_2026-10-20_TEST.pdf | D18: Subpoena, return date Tue 2026-10-20
A19: File | B19: F-05 | C19: court_order_TCT-800001_TEST.pdf | D19: Court order, Tri-County
A20: File | B20: F-06 | C20: authorization_wc_general_TEST.pdf | D20: Workers' comp authorization, names no protected categories
A21: File | B21: F-07 | C21: wcb_request_TEST.pdf | D21: Board request letter
A22: File | B22: F-08 | C22: not_allowed_TEST.exe | D22: Disallowed file type
... A48: Test request | B48: R-U | C48: RQ-01 / CL-01 / F-02 / Expedite=Yes | D48: Received Mon 2026-10-05 09:00 ET. Authorization names mental health records

Sheet Defect log
A1: EREQ-2147 UAT workbook: Expedited request option
A2: Prepared 2026-09-28 from the EREQ-2147 ticket, Harborline MSA (2023) + Amendment 2 (2026), Tri-County Services Agreement (2024). Due dates from business_days.py.
A3: PROVISIONAL: modules, severity rubric and holiday calendar are the SAMPLE reference files. Confirm with Heidy before sign-off (OQ-12).
A5: Defect ID | B5: Case ID | C5: Summary | D5: Steps to reproduce | E5: Expected | F5: Actual | G5: Severity | H5: Status | I5: Found by | J5: Date found | K5: Assigned to
A6: D-001
A7: D-002
A8: D-003
A9: D-004
A10: D-005
A11: D-006
A12: D-007
A13: D-008
A14: D-009
A15: D-010
A16: D-011
A17: D-012
... A35: D-030

Sheet Severity rubric
A1: EREQ-2147 UAT workbook: Expedited request option
A2: Prepared 2026-09-28 from the EREQ-2147 ticket, Harborline MSA (2023) + Amendment 2 (2026), Tri-County Services Agreement (2024). Due dates from business_days.py.
A3: PROVISIONAL: modules, severity rubric and holiday calendar are the SAMPLE reference files. Confirm with Heidy before sign-off (OQ-12).
A5: Level | B5: Definition | C5: ClaimFox examples | D5: Release decision | E5: Fix target
A6: S1 Critical | B6: Wrong records could be released, personal data exposed, or money or due dates calculated wrong across many requests. No workaround. | C6: A redaction is skipped; a request is attached to the wrong claim; the due-date calculation is wrong for a request type or client; invoices bill the wrong amount | D6: Blocks release | E6: Before release
A7: S2 Major | B7: A core step fails or gives wrong results for some requests, or a single request shows a wrong date or amount. A workaround exists but is manual or risky. | C7: The expedite fee is missing on some invoices; the queue doesn't sort expedited requests first; one confirmation email shows the wrong date | D7: Blocks release unless the owner signs off on a workaround | E7: Before release, or a hotfix within 5 business days
A8: S3 Minor | B8: Works, but confusing, inconsistent or slow. No data or money impact. | C8: Badge color is hard to read; a report column is mislabeled; a missing tooltip | D8: Doesn't block | E8: Next release
A9: S4 Cosmetic | B9: Typos, spacing, visual polish. | C9: Misspelled label; misaligned button | D9: Doesn't block | E9: Backlog
A10: Triage rule 1 | B10: Anything touching redaction, page selection, claim matching, or who receives records starts at S1 until proven otherwise.
A11: Triage rule 2 | B11: Money or due dates: S1 if the calculation itself is wrong (wrong everywhere), S2 if one request or one screen shows the wrong value.
A12: Triage rule 3 | B12: If a defect can't be reproduced twice, log it as Needs repro, not a severity.
